Workbook
Name oi: #REF!
Name Slicer_Classificação: #N/A
Name Slicer_Data: #N/A
Name Slicer_Data1: #N/A
Name Slicer_Data2: #N/A
Name Slicer_Data3: #N/A
Name Slicer_Data4: #N/A
Name Slicer_Instituição: #N/A
Name Slicer_Subclassificação: #N/A

Sheet Investimentos_Main
B3: Investimentos
B4: Data | C4: Nome | D4: Ticker | E4: Instituição | F4: Estratégia | G4: Quantidade | H4: Cotação Ativo | I4: Moeda Base | J4: Cotação Dolar | K4: Total (R$)
B5: 45078 | C5: Bitcoin | D5: BTC | E5: Ledger | G5: 0.179195 | H5: {=_xlfn.XLOOKUP(Table_Investimentos_Main[[#This Row],[Data]]&Table_Investimentos_Main[[#This Row],[Ticker]],Table_Cotacoes[Data]&Table_Cotacoes[Ticker],Table_Cotacoes[Valor],"")} -> 135052 | I5: =IF(Table_Investimentos_Main[[#This Row],[Ticker]]<>"",_xlfn.XLOOKUP(Table_Investimentos_Main[[#This Row],[Ticker]],Table_Cotacoes[Ticker],Table_Cotacoes[Moeda Base],""),"BRL") -> BTC | J5: {=_xlfn.SINGLE(_xlfn.XLOOKUP(Table_Investimentos_Main[[#This Row],[Data]]&"USD",Table_Cotacoes[Data]&Table_Cotacoes[Ticker],Table_Cotacoes[Valor],""))} -> 5.007 | K5: =IF(Table_Investimentos_Main[[#This Row],[Ticker]]<>"",Table_Investimentos_Main[[#This Row],[Quantidade]]*Table_Investimentos_Main[[#This Row],[Cotação Ativo]],Table_Investimentos_Main[[#This Row],[Quantidade]]) -> 24200.643
B6: 45078 | C6: Liquidez Diaria | E6: PicPay | G6: 3698.14 | H6: {=_xlfn.XLOOKUP(Table_Investimentos_Main[[#This Row],[Data]]&Table_Investimentos_Main[[#This Row],[Ticker]],Table_Cotacoes[Data]&Table_Cotacoes[Ticker],Table_Cotacoes[Valor],"")} | I6: =IF(Table_Investimentos_Main[[#This Row],[Ticker]]<>"",_xlfn.XLOOKUP(Table_Investimentos_Main[[#This Row],[Ticker]],Table_Cotacoes[Ticker],Table_Cotacoes[Moeda Base],""),"BRL") -> BRL | J6: {=_xlfn.SINGLE(_xlfn.XLOOKUP(Table_Investimentos_Main[[#This Row],[Data]]&"USD",Table_Cotacoes[Data]&Table_Cotacoes[Ticker],Table_Cotacoes[Valor],""))} -> 5.007 | K6: =IF(Table_Investimentos_Main[[#This Row],[Ticker]]<>"",Table_Investimentos_Main[[#This Row],[Quantidade]]*Table_Investimentos_Main[[#This Row],[Cotação Ativo]],Table_Investimentos_Main[[#This Row],[Quantidade]]) -> 3698.14
B7: 45078 | C7: CDB - 110% | E7: C6 | G7: 20017.71 | H7: {=_xlfn.XLOOKUP(Table_Investimentos_Main[[#This Row],[Data]]&Table_Investimentos_Main[[#This Row],[Ticker]],Table_Cotacoes[Data]&Table_Cotacoes[Ticker],Table_Cotacoes[Valor],"")} | I7: =IF(Table_Investimentos_Main[[#This Row],[Ticker]]<>"",_xlfn.XLOOKUP(Table_Investimentos_Main[[#This Row],[Ticker]],Table_Cotacoes[Ticker],Table_Cotacoes[Moeda Base],""),"BRL") -> BRL | J7: {=_xlfn.SINGLE(_xlfn.XLOOKUP(Table_Investimentos_Main[[#This Row],[Data]]&"USD",Table_Cotacoes[Data]&Table_Cotacoes[Ticker],Table_Cotacoes[Valor],""))} -> 5.007 | K7: =IF(Table_Investimentos_Main[[#This Row],[Ticker]]<>"",Table_Investimentos_Main[[#This Row],[Quantidade]]*Table_Investimentos_Main[[#This Row],[Cotação Ativo]],Table_Investimentos_Main[[#This Row],[Quantidade]]) -> 20017.71
B8: 45078 | C8: USDT | D8: USD | E8: Binance | G8: 1002 | H8: {=_xlfn.XLOOKUP(Table_Investimentos_Main[[#This Row],[Data]]&Table_Investimentos_Main[[#This Row],[Ticker]],Table_Cotacoes[Data]&Table_Cotacoes[Ticker],Table_Cotacoes[Valor],"")} -> 5.007 | I8: =IF(Table_Investimentos_Main[[#This Row],[Ticker]]<>"",_xlfn.XLOOKUP(Table_Investimentos_Main[[#This Row],[Ticker]],Table_Cotacoes[Ticker],Table_Cotacoes[Moeda Base],""),"BRL") -> USD | J8: {=_xlfn.SINGLE(_xlfn.XLOOKUP(Table_Investimentos_Main[[#This Row],[Data]]&"USD",Table_Cotacoes[Data]&Table_Cotacoes[Ticker],Table_Cotacoes[Valor],""))} -> 5.007 | K8: =IF(Table_Investimentos_Main[[#This Row],[Ticker]]<>"",Table_Investimentos_Main[[#This Row],[Quantidade]]*Table_Investimentos_Main[[#This Row],[Cotação Ativo]],Table_Investimentos_Main[[#This Row],[Quantidade]]) -> 5017.014
B9: 45078 | C9: BUSD | D9: USD | E9: Binance | G9: 2527 | H9: {=_xlfn.XLOOKUP(Table_Investimentos_Main[[#This Row],[Data]]&Table_Investimentos_Main[[#This Row],[Ticker]],Table_Cotacoes[Data]&Table_Cotacoes[Ticker],Table_Cotacoes[Valor],"")} -> 5.007 | I9: =IF(Table_Investimentos_Main[[#This Row],[Ticker]]<>"",_xlfn.XLOOKUP(Table_Investimentos_Main[[#This Row],[Ticker]],Table_Cotacoes[Ticker],Table_Cotacoes[Moeda Base],""),"BRL") -> USD | J9: {=_xlfn.SINGLE(_xlfn.XLOOKUP(Table_Investimentos_Main[[#This Row],[Data]]&"USD",Table_Cotacoes[Data]&Table_Cotacoes[Ticker],Table_Cotacoes[Valor],""))} -> 5.007 | K9: =IF(Table_Investimentos_Main[[#This Row],[Ticker]]<>"",Table_Investimentos_Main[[#This Row],[Quantidade]]*Table_Investimentos_Main[[#This Row],[Cotação Ativo]],Table_Investimentos_Main[[#This Row],[Quantidade]]) -> 12652.689
B10: 45078 | C10: Dolar | D10: USD | E10: Inter | G10: 99.79 | H10: {=_xlfn.XLOOKUP(Table_Investimentos_Main[[#This Row],[Data]]&Table_Investimentos_Main[[#This Row],[Ticker]],Table_Cotacoes[Data]&Table_Cotacoes[Ticker],Table_Cotacoes[Valor],"")} -> 5.007 | I10: =IF(Table_Investimentos_Main[[#This Row],[Ticker]]<>"",_xlfn.XLOOKUP(Table_Investimentos_Main[[#This Row],[Ticker]],Table_Cotacoes[Ticker],Table_Cotacoes[Moeda Base],""),"BRL") -> USD | J10: {=_xlfn.SINGLE(_xlfn.XLOOKUP(Table_Investimentos_Main[[#This Row],[Data]]&"USD",Table_Cotacoes[Data]&Table_Cotacoes[Ticker],Table_Cotacoes[Valor],""))} -> 5.007 | K10: =IF(Table_Investimentos_Main[[#This Row],[Ticker]]<>"",Table_Investimentos_Main[[#This Row],[Quantidade]]*Table_Investimentos_Main[[#This Row],[Cotação Ativo]],Table_Investimentos_Main[[#This Row],[Quantidade]]) -> 499.64853
B11: 45108 | C11: Bitcoin | D11: BTC | E11: Ledger | G11: 0.179195 | H11: {=_xlfn.XLOOKUP(Table_Investimentos_Main[[#This Row],[Data]]&Table_Investimentos_Main[[#This Row],[Ticker]],Table_Cotacoes[Data]&Table_Cotacoes[Ticker],Table_Cotacoes[Valor],"")} -> 151373.22 | I11: =IF(Table_Investimentos_Main[[#This Row],[Ticker]]<>"",_xlfn.XLOOKUP(Table_Investimentos_Main[[#This Row],[Ticker]],Table_Cotacoes[Ticker],Table_Cotacoes[Moeda Base],""),"BRL") -> BTC | J11: {=_xlfn.SINGLE(_xlfn.XLOOKUP(Table_Investimentos_Main[[#This Row],[Data]]&"USD",Table_Cotacoes[Data]&Table_Cotacoes[Ticker],Table_Cotacoes[Valor],""))} -> 4.89 | K11: =IF(Table_Investimentos_Main[[#This Row],[Ticker]]<>"",Table_Investimentos_Main[[#This Row],[Quantidade]]*Table_Investimentos_Main[[#This Row],[Cotação Ativo]],Table_Investimentos_Main[[#This Row],[Quantidade]]) -> 27125.324
B12: 45108 | C12: Liquidez Diaria | E12: PicPay | G12: 4238.83 | H12: {=_xlfn.XLOOKUP(Table_Investimentos_Main[[#This Row],[Data]]&Table_Investimentos_Main[[#This Row],[Ticker]],Table_Cotacoes[Data]&Table_Cotacoes[Ticker],Table_Cotacoes[Valor],"")} | I12: =IF(Table_Investimentos_Main[[#This Row],[Ticker]]<>"",_xlfn.XLOOKUP(Table_Investimentos_Main[[#This Row],[Ticker]],Table_Cotacoes[Ticker],Table_Cotacoes[Moeda Base],""),"BRL") -> BRL | J12: {=_xlfn.SINGLE(_xlfn.XLOOKUP(Table_Investimentos_Main[[#This Row],[Data]]&"USD",Table_Cotacoes[Data]&Table_Cotacoes[Ticker],Table_Cotacoes[Valor],""))} -> 4.89 | K12: =IF(Table_Investimentos_Main[[#This Row],[Ticker]]<>"",Table_Investimentos_Main[[#This Row],[Quantidade]]*Table_Investimentos_Main[[#This Row],[Cotação Ativo]],Table_Investimentos_Main[[#This Row],[Quantidade]]) -> 4238.83
B13: 45108 | C13: CDB - 110% | E13: C6 | G13: 20277.35 | H13: {=_xlfn.XLOOKUP(Table_Investimentos_Main[[#This Row],[Data]]&Table_Investimentos_Main[[#This Row],[Ticker]],Table_Cotacoes[Data]&Table_Cotacoes[Ticker],Table_Cotacoes[Valor],"")} | I13: =IF(Table_Investimentos_Main[[#This Row],[Ticker]]<>"",_xlfn.XLOOKUP(Table_Investimentos_Main[[#This Row],[Ticker]],Table_Cotacoes[Ticker],Table_Cotacoes[Moeda Base],""),"BRL") -> BRL | J13: {=_xlfn.SINGLE(_xlfn.XLOOKUP(Table_Investimentos_Main[[#This Row],[Data]]&"USD",Table_Cotacoes[Data]&Table_Cotacoes[Ticker],Table_Cotacoes[Valor],""))} -> 4.89 | K13: =IF(Table_Investimentos_Main[[#This Row],[Ticker]]<>"",Table_Investimentos_Main[[#This Row],[Quantidade]]*Table_Investimentos_Main[[#This Row],[Cotação Ativo]],Table_Investimentos_Main[[#This Row],[Quantidade]]) -> 20277.35
B14: 45108 | C14: USDT | D14: USD | E14: Binance | G14: 1009 | H14: {=_xlfn.XLOOKUP(Table_Investimentos_Main[[#This Row],[Data]]&Table_Investimentos_Main[[#This Row],[Ticker]],Table_Cotacoes[Data]&Table_Cotacoes[Ticker],Table_Cotacoes[Valor],"")} -> 4.89 | I14: =IF(Table_Investimentos_Main[[#This Row],[Ticker]]<>"",_xlfn.XLOOKUP(Table_Investimentos_Main[[#This Row],[Ticker]],Table_Cotacoes[Ticker],Table_Cotacoes[Moeda Base],""),"BRL") -> USD | J14: {=_xlfn.SINGLE(_xlfn.XLOOKUP(Table_Investimentos_Main[[#This Row],[Data]]&"USD",Table_Cotacoes[Data]&Table_Cotacoes[Ticker],Table_Cotacoes[Valor],""))} -> 4.89 | K14: =IF(Table_Investimentos_Main[[#This Row],[Ticker]]<>"",Table_Investimentos_Main[[#This Row],[Quantidade]]*Table_Investimentos_Main[[#This Row],[Cotação Ativo]],Table_Investimentos_Main[[#This Row],[Quantidade]]) -> 4934.01
B15: 45108 | C15: BUSD | D15: USD | E15: Binance | G15: 2529 | H15: {=_xlfn.XLOOKUP(Table_Investimentos_Main[[#This Row],[Data]]&Table_Investimentos_Main[[#This Row],[Ticker]],Table_Cotacoes[Data]&Table_Cotacoes[Ticker],Table_Cotacoes[Valor],"")} -> 4.89 | I15: =IF(Table_Investimentos_Main[[#This Row],[Ticker]]<>"",_xlfn.XLOOKUP(Table_Investimentos_Main[[#This Row],[Ticker]],Table_Cotacoes[Ticker],Table_Cotacoes[Moeda Base],""),"BRL") -> USD | J15: {=_xlfn.SINGLE(_xlfn.XLOOKUP(Table_Investimentos_Main[[#This Row],[Data]]&"USD",Table_Cotacoes[Data]&Table_Cotacoes[Ticker],Table_Cotacoes[Valor],""))} -> 4.89 | K15: =IF(Table_Investimentos_Main[[#This Row],[Ticker]]<>"",Table_Investimentos_Main[[#This Row],[Quantidade]]*Table_Investimentos_Main[[#This Row],[Cotação Ativo]],Table_Investimentos_Main[[#This Row],[Quantidade]]) -> 12366.81
B16: 45108 | C16: Dolar | D16: USD | E16: Inter | G16: 99.79 | H16: {=_xlfn.XLOOKUP(Table_Investimentos_Main[[#This Row],[Data]]&Table_Investimentos_Main[[#This Row],[Ticker]],Table_Cotacoes[Data]&Table_Cotacoes[Ticker],Table_Cotacoes[Valor],"")} -> 4.89 | I16: =IF(Table_Investimentos_Main[[#This Row],[Ticker]]<>"",_xlfn.XLOOKUP(Table_Investimentos_Main[[#This Row],[Ticker]],Table_Cotacoes[Ticker],Table_Cotacoes[Moeda Base],""),"BRL") -> USD | J16: {=_xlfn.SINGLE(_xlfn.XLOOKUP(Table_Investimentos_Main[[#This Row],[Data]]&"USD",Table_Cotacoes[Data]&Table_Cotacoes[Ticker],Table_Cotacoes[Valor],""))} -> 4.89 | K16: =IF(Table_Investimentos_Main[[#This Row],[Ticker]]<>"",Table_Investimentos_Main[[#This Row],[Quantidade]]*Table_Investimentos_Main[[#This Row],[Cotação Ativo]],Table_Investimentos_Main[[#This Row],[Quantidade]]) -> 487.9731
B17: 45200 | C17: Bitcoin | D17: BTC | E17: Binance | G17: 0.01745788 | H17: {=_xlfn.XLOOKUP(Table_Investimentos_Main[[#This Row],[Data]]&Table_Investimentos_Main[[#This Row],[Ticker]],Table_Cotacoes[Data]&Table_Cotacoes[Ticker],Table_Cotacoes[Valor],"")} -> 174262.84 | I17: =IF(Table_Investimentos_Main[[#This Row],[Ticker]]<>"",_xlfn.XLOOKUP(Table_Investimentos_Main[[#This Row],[Ticker]],Table_Cotacoes[Ticker],Table_Cotacoes[Moeda Base],""),"BRL") -> BTC | J17: {=_xlfn.SINGLE(_xlfn.XLOOKUP(Table_Investimentos_Main[[#This Row],[Data]]&"USD",Table_Cotacoes[Data]&Table_Cotacoes[Ticker],Table_Cotacoes[Valor],""))} -> 5.05 | K17: =IF(Table_Investimentos_Main[[#This Row],[Ticker]]<>"",Table_Investimentos_Main[[#This Row],[Quantidade]]*Table_Investimentos_Main[[#This Row],[Cotação Ativo]],Table_Investimentos_Main[[#This Row],[Quantidade]]) -> 3042.2597
B18: 45200 | C18: Bitcoin | D18: BTC | E18: Ledger | G18: 0.179195 | H18: {=_xlfn.XLOOKUP(Table_Investimentos_Main[[#This Row],[Data]]&Table_Investimentos_Main[[#This Row],[Ticker]],Table_Cotacoes[Data]&Table_Cotacoes[Ticker],Table_Cotacoes[Valor],"")} -> 174262.84 | I18: =IF(Table_Investimentos_Main[[#This Row],[Ticker]]<>"",_xlfn.XLOOKUP(Table_Investimentos_Main[[#This Row],[Ticker]],Table_Cotacoes[Ticker],Table_Cotacoes[Moeda Base],""),"BRL") -> BTC | J18: {=_xlfn.SINGLE(_xlfn.XLOOKUP(Table_Investimentos_Main[[#This Row],[Data]]&"USD",Table_Cotacoes[Data]&Table_Cotacoes[Ticker],Table_Cotacoes[Valor],""))} -> 5.05 | K18: =IF(Table_Investimentos_Main[[#This Row],[Ticker]]<>"",Table_Investimentos_Main[[#This Row],[Quantidade]]*Table_Investimentos_Main[[#This Row],[Cotação Ativo]],Table_Investimentos_Main[[#This Row],[Quantidade]]) -> 31227.03
B19: 45200 | C19: Inter | E19: Inter | G19: 5573.41 | H19: {=_xlfn.XLOOKUP(Table_Investimentos_Main[[#This Row],[Data]]&Table_Investimentos_Main[[#This Row],[Ticker]],Table_Cotacoes[Data]&Table_Cotacoes[Ticker],Table_Cotacoes[Valor],"")} | I19: =IF(Table_Investimentos_Main[[#This Row],[Ticker]]<>"",_xlfn.XLOOKUP(Table_Investimentos_Main[[#This Row],[Ticker]],Table_Cotacoes[Ticker],Table_Cotacoes[Moeda Base],""),"BRL") -> BRL | J19: {=_xlfn.SINGLE(_xlfn.XLOOKUP(Table_Investimentos_Main[[#This Row],[Data]]&"USD",Table_Cotacoes[Data]&Table_Cotacoes[Ticker],Table_Cotacoes[Valor],""))} -> 5.05 | K19: =IF(Table_Investimentos_Main[[#This Row],[Ticker]]<>"",Table_Investimentos_Main[[#This Row],[Quantidade]]*Table_Investimentos_Main[[#This Row],[Cotação Ativo]],Table_Investimentos_Main[[#This Row],[Quantidade]]) -> 5573.41
B20: 45200 | C20: C6 - CDB Diario 105% | E20: C6 | G20: 975 | H20: {=_xlfn.XLOOKUP(Table_Investimentos_Main[[#This Row],[Data]]&Table_Investimentos_Main[[#This Row],[Ticker]],Table_Cotacoes[Data]&Table_Cotacoes[Ticker],Table_Cotacoes[Valor],"")} | I20: =IF(Table_Investimentos_Main[[#This Row],[Ticker]]<>"",_xlfn.XLOOKUP(Table_Investimentos_Main[[#This Row],[Ticker]],Table_Cotacoes[Ticker],Table_Cotacoes[Moeda Base],""),"BRL") -> BRL | J20: {=_xlfn.SINGLE(_xlfn.XLOOKUP(Table_Investimentos_Main[[#This Row],[Data]]&"USD",Table_Cotacoes[Data]&Table_Cotacoes[Ticker],Table_Cotacoes[Valor],""))} -> 5.05 | K20: =IF(Table_Investimentos_Main[[#This Row],[Ticker]]<>"",Table_Investimentos_Main[[#This Row],[Quantidade]]*Table_Investimentos_Main[[#This Row],[Cotação Ativo]],Table_Investimentos_Main[[#This Row],[Quantidade]]) -> 975
B21: 45200 | C21: C6 - CDB Cartao 100% | E21: C6 | G21: 2500 | H21: {=_xlfn.XLOOKUP(Table_Investimentos_Main[[#This Row],[Data]]&Table_Investimentos_Main[[#This Row],[Ticker]],Table_Cotacoes[Data]&Table_Cotacoes[Ticker],Table_Cotacoes[Valor],"")} | I21: =IF(Table_Investimentos_Main[[#This Row],[Ticker]]<>"",_xlfn.XLOOKUP(Table_Investimentos_Main[[#This Row],[Ticker]],Table_Cotacoes[Ticker],Table_Cotacoes[Moeda Base],""),"BRL") -> BRL | J21: {=_xlfn.SINGLE(_xlfn.XLOOKUP(Table_Investimentos_Main[[#This Row],[Data]]&"USD",Table_Cotacoes[Data]&Table_Cotacoes[Ticker],Table_Cotacoes[Valor],""))} -> 5.05 | K21: =IF(Table_Investimentos_Main[[#This Row],[Ticker]]<>"",Table_Investimentos_Main[[#This Row],[Quantidade]]*Table_Investimentos_Main[[#This Row],[Cotação Ativo]],Table_Investimentos_Main[[#This Row],[Quantidade]]) -> 2500
B22: 45200 | C22: LCI DI 180 | E22: Inter | G22: 15748.75 | H22: {=_xlfn.XLOOKUP(Table_Investimentos_Main[[#This Row],[Data]]&Table_Investimentos_Main[[#This Row],[Ticker]],Table_Cotacoes[Data]&Table_Cotacoes[Ticker],Table_Cotacoes[Valor],"")} | I22: =IF(Table_Investimentos_Main[[#This Row],[Ticker]]<>"",_xlfn.XLOOKUP(Table_Investimentos_Main[[#This Row],[Ticker]],Table_Cotacoes[Ticker],Table_Cotacoes[Moeda Base],""),"BRL") -> BRL | J22: {=_xlfn.SINGLE(_xlfn.XLOOKUP(Table_Investimentos_Main[[#This Row],[Data]]&"USD",Table_Cotacoes[Data]&Table_Cotacoes[Ticker],Table_Cotacoes[Valor],""))} -> 5.05 | K22: =IF(Table_Investimentos_Main[[#This Row],[Ticker]]<>"",Table_Investimentos_Main[[#This Row],[Quantidade]]*Table_Investimentos_Main[[#This Row],[Cotação Ativo]],Table_Investimentos_Main[[#This Row],[Quantidade]]) -> 15748.75
B23: 45200 | C23: USDT | D23: USD | E23: Binance | G23: 1017.85 | H23: {=_xlfn.XLOOKUP(Table_Investimentos_Main[[#This Row],[Data]]&Table_Investimentos_Main[[#This Row],[Ticker]],Table_Cotacoes[Data]&Table_Cotacoes[Ticker],Table_Cotacoes[Valor],"")} -> 5.05 | I23: =IF(Table_Investimentos_Main[[#This Row],[Ticker]]<>"",_xlfn.XLOOKUP(Table_Investimentos_Main[[#This Row],[Ticker]],Table_Cotacoes[Ticker],Table_Cotacoes[Moeda Base],""),"BRL") -> USD | J23: {=_xlfn.SINGLE(_xlfn.XLOOKUP(Table_Investimentos_Main[[#This Row],[Data]]&"USD",Table_Cotacoes[Data]&Table_Cotacoes[Ticker],Table_Cotacoes[Valor],""))} -> 5.05 | K23: =IF(Table_Investimentos_Main[[#This Row],[Ticker]]<>"",Table_Investimentos_Main[[#This Row],[Quantidade]]*Table_Investimentos_Main[[#This Row],[Cotação Ativo]],Table_Investimentos_Main[[#This Row],[Quantidade]]) -> 5140.1425
B24: 45200 | C24: BUSD | D24: USD | E24: Binance | G24: 2531.36 | H24: {=_xlfn.XLOOKUP(Table_Investimentos_Main[[#This Row],[Data]]&Table_Investimentos_Main[[#This Row],[Ticker]],Table_Cotacoes[Data]&Table_Cotacoes[Ticker],Table_Cotacoes[Valor],"")} -> 5.05 | I24: =IF(Table_Investimentos_Main[[#This Row],[Ticker]]<>"",_xlfn.XLOOKUP(Table_Investimentos_Main[[#This Row],[Ticker]],Table_Cotacoes[Ticker],Table_Cotacoes[Moeda Base],""),"BRL") -> USD | J24: {=_xlfn.SINGLE(_xlfn.XLOOKUP(Table_Investimentos_Main[[#This Row],[Data]]&"USD",Table_Cotacoes[Data]&Table_Cotacoes[Ticker],Table_Cotacoes[Valor],""))} -> 5.05 | K24: =IF(Table_Investimentos_Main[[#This Row],[Ticker]]<>"",Table_Investimentos_Main[[#This Row],[Quantidade]]*Table_Investimentos_Main[[#This Row],[Cotação Ativo]],Table_Investimentos_Main[[#This Row],[Quantidade]]) -> 12783.368
B25: 45200 | C25: C6- Parado | E25: C6 | G25: 30.62 | H25: {=_xlfn.XLOOKUP(Table_Investimentos_Main[[#This Row],[Data]]&Table_Investimentos_Main[[#This Row],[Ticker]],Table_Cotacoes[Data]&Table_Cotacoes[Ticker],Table_Cotacoes[Valor],"")} | I25: =IF(Table_Investimentos_Main[[#This Row],[Ticker]]<>"",_xlfn.XLOOKUP(Table_Investimentos_Main[[#This Row],[Ticker]],Table_Cotacoes[Ticker],Table_Cotacoes[Moeda Base],""),"BRL") -> BRL | J25: {=_xlfn.SINGLE(_xlfn.XLOOKUP(Table_Investimentos_Main[[#This Row],[Data]]&"USD",Table_Cotacoes[Data]&Table_Cotacoes[Ticker],Table_Cotacoes[Valor],""))} -> 5.05 | K25: =IF(Table_Investimentos_Main[[#This Row],[Ticker]]<>"",Table_Investimentos_Main[[#This Row],[Quantidade]]*Table_Investimentos_Main[[#This Row],[Cotação Ativo]],Table_Investimentos_Main[[#This Row],[Quantidade]]) -> 30.62
B26: 45200 | C26: Dolar | D26: USD | E26: Inter | G26: 39.94 | H26: {=_xlfn.XLOOKUP(Table_Investimentos_Main[[#This Row],[Data]]&Table_Investimentos_Main[[#This Row],[Ticker]],Table_Cotacoes[Data]&Table_Cotacoes[Ticker],Table_Cotacoes[Valor],"")} -> 5.05 | I26: =IF(Table_Investimentos_Main[[#This Row],[Ticker]]<>"",_xlfn.XLOOKUP(Table_Investimentos_Main[[#This Row],[Ticker]],Table_Cotacoes[Ticker],Table_Cotacoes[Moeda Base],""),"BRL") -> USD | J26: {=_xlfn.SINGLE(_xlfn.XLOOKUP(Table_Investimentos_Main[[#This Row],[Data]]&"USD",Table_Cotacoes[Data]&Table_Cotacoes[Ticker],Table_Cotacoes[Valor],""))} -> 5.05 | K26: =IF(Table_Investimentos_Main[[#This Row],[Ticker]]<>"",Table_Investimentos_Main[[#This Row],[Quantidade]]*Table_Investimentos_Main[[#This Row],[Cotação Ativo]],Table_Investimentos_Main[[#This Row],[Quantidade]]) -> 201.697
B27: 45261 | C27: USDT | D27: USD | E27: Binance | G27: 1025.86 | H27: {=_xlfn.XLOOKUP(Table_Investimentos_Main[[#This Row],[Data]]&Table_Investimentos_Main[[#This Row],[Ticker]],Table_Cotacoes[Data]&Table_Cotacoes[Ticker],Table_Cotacoes[Valor],"")} -> 4.95 | I27: =IF(Table_Investimentos_Main[[#This Row],[Ticker]]<>"",_xlfn.XLOOKUP(Table_Investimentos_Main[[#This Row],[Ticker]],Table_Cotacoes[Ticker],Table_Cotacoes[Moeda Base],""),"BRL") -> USD | J27: {=_xlfn.SINGLE(_xlfn.XLOOKUP(Table_Investimentos_Main[[#This Row],[Data]]&"USD",Table_Cotacoes[Data]&Table_Cotacoes[Ticker],Table_Cotacoes[Valor],""))} -> 4.95 | K27: =IF(Table_Investimentos_Main[[#This Row],[Ticker]]<>"",Table_Investimentos_Main[[#This Row],[Quantidade]]*Table_Investimentos_Main[[#This Row],[Cotação Ativo]],Table_Investimentos_Main[[#This Row],[Quantidade]]) -> 5078.007
B28: 45261 | C28: BUSD | D28: USD | E28: Binance | G28: 2539.94 | H28: {=_xlfn.XLOOKUP(Table_Investimentos_Main[[#This Row],[Data]]&Table_Investimentos_Main[[#This Row],[Ticker]],Table_Cotacoes[Data]&Table_Cotacoes[Ticker],Table_Cotacoes[Valor],"")} -> 4.95 | I28: =IF(Table_Investimentos_Main[[#This Row],[Ticker]]<>"",_xlfn.XLOOKUP(Table_Investimentos_Main[[#This Row],[Ticker]],Table_Cotacoes[Ticker],Table_Cotacoes[Moeda Base],""),"BRL") -> USD | J28: {=_xlfn.SINGLE(_xlfn.XLOOKUP(Table_Investimentos_Main[[#This Row],[Data]]&"USD",Table_Cotacoes[Data]&Table_Cotacoes[Ticker],Table_Cotacoes[Valor],""))} -> 4.95 | K28: =IF(Table_Investimentos_Main[[#This Row],[Ticker]]<>"",Table_Investimentos_Main[[#This Row],[Quantidade]]*Table_Investimentos_Main[[#This Row],[Cotação Ativo]],Table_Investimentos_Main[[#This Row],[Quantidade]]) -> 12572.703
B29: 45261 | C29: Conta Bancária | E29: C6 | G29: 471.12 | H29: {=_xlfn.XLOOKUP(Table_Investimentos_Main[[#This Row],[Data]]&Table_Investimentos_Main[[#This Row],[Ticker]],Table_Cotacoes[Data]&Table_Cotacoes[Ticker],Table_Cotacoes[Valor],"")} | I29: =IF(Table_Investimentos_Main[[#This Row],[Ticker]]<>"",_xlfn.XLOOKUP(Table_Investimentos_Main[[#This Row],[Ticker]],Table_Cotacoes[Ticker],Table_Cotacoes[Moeda Base],""),"BRL") -> BRL | J29: {=_xlfn.SINGLE(_xlfn.XLOOKUP(Table_Investimentos_Main[[#This Row],[Data]]&"USD",Table_Cotacoes[Data]&Table_Cotacoes[Ticker],Table_Cotacoes[Valor],""))} -> 4.95 | K29: =IF(Table_Investimentos_Main[[#This Row],[Ticker]]<>"",Table_Investimentos_Main[[#This Row],[Quantidade]]*Table_Investimentos_Main[[#This Row],[Cotação Ativo]],Table_Investimentos_Main[[#This Row],[Quantidade]]) -> 471.12
B30: 45261 | C30: Dólar | D30: USD | E30: Inter | G30: 39.94 | H30: {=_xlfn.XLOOKUP(Table_Investimentos_Main[[#This Row],[Data]]&Table_Investimentos_Main[[#This Row],[Ticker]],Table_Cotacoes[Data]&Table_Cotacoes[Ticker],Table_Cotacoes[Valor],"")} -> 4.95 | I30: =IF(Table_Investimentos_Main[[#This Row],[Ticker]]<>"",_xlfn.XLOOKUP(Table_Investimentos_Main[[#This Row],[Ticker]],Table_Cotacoes[Ticker],Table_Cotacoes[Moeda Base],""),"BRL") -> USD | J30: {=_xlfn.SINGLE(_xlfn.XLOOKUP(Table_Investimentos_Main[[#This Row],[Data]]&"USD",Table_Cotacoes[Data]&Table_Cotacoes[Ticker],Table_Cotacoes[Valor],""))} -> 4.95 | K30: =IF(Table_Investimentos_Main[[#This Row],[Ticker]]<>"",Table_Investimentos_Main[[#This Row],[Quantidade]]*Table_Investimentos_Main[[#This Row],[Cotação Ativo]],Table_Investimentos_Main[[#This Row],[Quantidade]]) -> 197.703
B31: 45261 | C31: Bitcoin | D31: BTC | E31: Binance | G31: 0.01745788 | H31: {=_xlfn.XLOOKUP(Table_Investimentos_Main[[#This Row],[Data]]&Table_Investimentos_Main[[#This Row],[Ticker]],Table_Cotacoes[Data]&Table_Cotacoes[Ticker],Table_Cotacoes[Valor],"")} -> 207740.79 | I31: =IF(Table_Investimentos_Main[[#This Row],[Ticker]]<>"",_xlfn.XLOOKUP(Table_Investimentos_Main[[#This Row],[Ticker]],Table_Cotacoes[Ticker],Table_Cotacoes[Moeda Base],""),"BRL") -> BTC | J31: {=_xlfn.SINGLE(_xlfn.XLOOKUP(Table_Investimentos_Main[[#This Row],[Data]]&"USD",Table_Cotacoes[Data]&Table_Cotacoes[Ticker],Table_Cotacoes[Valor],""))} -> 4.95 | K31: =IF(Table_Investimentos_Main[[#This Row],[Ticker]]<>"",Table_Investimentos_Main[[#This Row],[Quantidade]]*Table_Investimentos_Main[[#This Row],[Cotação Ativo]],Table_Investimentos_Main[[#This Row],[Quantidade]]) -> 3626.7138
B32: 45261 | C32: Bitcoin | D32: BTC | E32: Ledger | G32: 0.179195 | H32: {=_xlfn.XLOOKUP(Table_Investimentos_Main[[#This Row],[Data]]&Table_Investimentos_Main[[#This Row],[Ticker]],Table_Cotacoes[Data]&Table_Cotacoes[Ticker],Table_Cotacoes[Valor],"")} -> 207740.79 | I32: =IF(Table_Investimentos_Main[[#This Row],[Ticker]]<>"",_xlfn.XLOOKUP(Table_Investimentos_Main[[#This Row],[Ticker]],Table_Cotacoes[Ticker],Table_Cotacoes[Moeda Base],""),"BRL") -> BTC | J32: {=_xlfn.SINGLE(_xlfn.XLOOKUP(Table_Investimentos_Main[[#This Row],[Data]]&"USD",Table_Cotacoes[Data]&Table_Cotacoes[Ticker],Table_Cotacoes[Valor],""))} -> 4.95 | K32: =IF(Table_Investimentos_Main[[#This Row],[Ticker]]<>"",Table_Investimentos_Main[[#This Row],[Quantidade]]*Table_Investimentos_Main[[#This Row],[Cotação Ativo]],Table_Investimentos_Main[[#This Row],[Quantidade]]) -> 37226.111
B33: 45261 | C33: CDB Diario 105% | E33: C6 | G33: 11887.95 | H33: {=_xlfn.XLOOKUP(Table_Investimentos_Main[[#This Row],[Data]]&Table_Investimentos_Main[[#This Row],[Ticker]],Table_Cotacoes[Data]&Table_Cotacoes[Ticker],Table_Cotacoes[Valor],"")} | I33: =IF(Table_Investimentos_Main[[#This Row],[Ticker]]<>"",_xlfn.XLOOKUP(Table_Investimentos_Main[[#This Row],[Ticker]],Table_Cotacoes[Ticker],Table_Cotacoes[Moeda Base],""),"BRL") -> BRL | J33: {=_xlfn.SINGLE(_xlfn.XLOOKUP(Table_Investimentos_Main[[#This Row],[Data]]&"USD",Table_Cotacoes[Data]&Table_Cotacoes[Ticker],Table_Cotacoes[Valor],""))} -> 4.95 | K33: =IF(Table_Investimentos_Main[[#This Row],[Ticker]]<>"",Table_Investimentos_Main[[#This Row],[Quantidade]]*Table_Investimentos_Main[[#This Row],[Cotação Ativo]],Table_Investimentos_Main[[#This Row],[Quantidade]]) -> 11887.95
B34: 45261 | C34: CDB Cartao 100% | E34: C6 | G34: 2567.31 | H34: {=_xlfn.XLOOKUP(Table_Investimentos_Main[[#This Row],[Data]]&Table_Investimentos_Main[[#This Row],[Ticker]],Table_Cotacoes[Data]&Table_Cotacoes[Ticker],Table_Cotacoes[Valor],"")} | I34: =IF(Table_Investimentos_Main[[#This Row],[Ticker]]<>"",_xlfn.XLOOKUP(Table_Investimentos_Main[[#This Row],[Ticker]],Table_Cotacoes[Ticker],Table_Cotacoes[Moeda Base],""),"BRL") -> BRL | J34: {=_xlfn.SINGLE(_xlfn.XLOOKUP(Table_Investimentos_Main[[#This Row],[Data]]&"USD",Table_Cotacoes[Data]&Table_Cotacoes[Ticker],Table_Cotacoes[Valor],""))} -> 4.95 | K34: =IF(Table_Investimentos_Main[[#This Row],[Ticker]]<>"",Table_Investimentos_Main[[#This Row],[Quantidade]]*Table_Investimentos_Main[[#This Row],[Cotação Ativo]],Table_Investimentos_Main[[#This Row],[Quantidade]]) -> 2567.31
B35: 45261 | C35: LCI DI 180 | E35: Inter | G35: 15900.21 | H35: {=_xlfn.XLOOKUP(Table_Investimentos_Main[[#This Row],[Data]]&Table_Investimentos_Main[[#This Row],[Ticker]],Table_Cotacoes[Data]&Table_Cotacoes[Ticker],Table_Cotacoes[Valor],"")} | I35: =IF(Table_Investimentos_Main[[#This Row],[Ticker]]<>"",_xlfn.XLOOKUP(Table_Investimentos_Main[[#This Row],[Ticker]],Table_Cotacoes[Ticker],Table_Cotacoes[Moeda Base],""),"BRL") -> BRL | J35: {=_xlfn.SINGLE(_xlfn.XLOOKUP(Table_Investimentos_Main[[#This Row],[Data]]&"USD",Table_Cotacoes[Data]&Table_Cotacoes[Ticker],Table_Cotacoes[Valor],""))} -> 4.95 | K35: =IF(Table_Investimentos_Main[[#This Row],[Ticker]]<>"",Table_Investimentos_Main[[#This Row],[Quantidade]]*Table_Investimentos_Main[[#This Row],[Cotação Ativo]],Table_Investimentos_Main[[#This Row],[Quantidade]]) -> 15900.21
B36: 45292 | C36: USDT | D36: USD | E36: Binance | G36: 1044.7 | H36: {=_xlfn.XLOOKUP(Table_Investimentos_Main[[#This Row],[Data]]&Table_Investimentos_Main[[#This Row],[Ticker]],Table_Cotacoes[Data]&Table_Cotacoes[Ticker],Table_Cotacoes[Valor],"")} -> 4.98 | I36: =IF(Table_Investimentos_Main[[#This Row],[Ticker]]<>"",_xlfn.XLOOKUP(Table_Investimentos_Main[[#This Row],[Ticker]],Table_Cotacoes[Ticker],Table_Cotacoes[Moeda Base],""),"BRL") -> USD | J36: {=_xlfn.SINGLE(_xlfn.XLOOKUP(Table_Investimentos_Main[[#This Row],[Data]]&"USD",Table_Cotacoes[Data]&Table_Cotacoes[Ticker],Table_Cotacoes[Valor],""))} -> 4.98 | K36: =IF(Table_Investimentos_Main[[#This Row],[Ticker]]<>"",Table_Investimentos_Main[[#This Row],[Quantidade]]*Table_Investimentos_Main[[#This Row],[Cotação Ativo]],Table_Investimentos_Main[[#This Row],[Quantidade]]) -> 5202.606
B37: 45292 | C37: BUSD | D37: USD | E37: Binance | G37: 2568.18 | H37: {=_xlfn.XLOOKUP(Table_Investimentos_Main[[#This Row],[Data]]&Table_Investimentos_Main[[#This Row],[Ticker]],Table_Cotacoes[Data]&Table_Cotacoes[Ticker],Table_Cotacoes[Valor],"")} -> 4.98 | I37: =IF(Table_Investimentos_Main[[#This Row],[Ticker]]<>"",_xlfn.XLOOKUP(Table_Investimentos_Main[[#This Row],[Ticker]],Table_Cotacoes[Ticker],Table_Cotacoes[Moeda Base],""),"BRL") -> USD | J37: {=_xlfn.SINGLE(_xlfn.XLOOKUP(Table_Investimentos_Main[[#This Row],[Data]]&"USD",Table_Cotacoes[Data]&Table_Cotacoes[Ticker],Table_Cotacoes[Valor],""))} -> 4.98 | K37: =IF(Table_Investimentos_Main[[#This Row],[Ticker]]<>"",Table_Investimentos_Main[[#This Row],[Quantidade]]*Table_Investimentos_Main[[#This Row],[Cotação Ativo]],Table_Investimentos_Main[[#This Row],[Quantidade]]) -> 12789.536
B38: 45292 | C38: Conta Bancária | E38: C6 | G38: 366.73 | H38: {=_xlfn.XLOOKUP(Table_Investimentos_Main[[#This Row],[Data]]&Table_Investimentos_Main[[#This Row],[Ticker]],Table_Cotacoes[Data]&Table_Cotacoes[Ticker],Table_Cotacoes[Valor],"")} | I38: =IF(Table_Investimentos_Main[[#This Row],[Ticker]]<>"",_xlfn.XLOOKUP(Table_Investimentos_Main[[#This Row],[Ticker]],Table_Cotacoes[Ticker],Table_Cotacoes[Moeda Base],""),"BRL") -> BRL | J38: {=_xlfn.SINGLE(_xlfn.XLOOKUP(Table_Investimentos_Main[[#This Row],[Data]]&"USD",Table_Cotacoes[Data]&Table_Cotacoes[Ticker],Table_Cotacoes[Valor],""))} -> 4.98 | K38: =IF(Table_Investimentos_Main[[#This Row],[Ticker]]<>"",Table_Investimentos_Main[[#This Row],[Quantidade]]*Table_Investimentos_Main[[#This Row],[Cotação Ativo]],Table_Investimentos_Main[[#This Row],[Quantidade]]) -> 366.73
B39: 45292 | C39: Dólar | D39: USD | E39: Inter | G39: 39.94 | H39: {=_xlfn.XLOOKUP(Table_Investimentos_Main[[#This Row],[Data]]&Table_Investimentos_Main[[#This Row],[Ticker]],Table_Cotacoes[Data]&Table_Cotacoes[Ticker],Table_Cotacoes[Valor],"")} -> 4.98 | I39: =IF(Table_Investimentos_Main[[#This Row],[Ticker]]<>"",_xlfn.XLOOKUP(Table_Investimentos_Main[[#This Row],[Ticker]],Table_Cotacoes[Ticker],Table_Cotacoes[Moeda Base],""),"BRL") -> USD | J39: {=_xlfn.SINGLE(_xlfn.XLOOKUP(Table_Investimentos_Main[[#This Row],[Data]]&"USD",Table_Cotacoes[Data]&Table_Cotacoes[Ticker],Table_Cotacoes[Valor],""))} -> 4.98 | K39: =IF(Table_Investimentos_Main[[#This Row],[Ticker]]<>"",Table_Investimentos_Main[[#This Row],[Quantidade]]*Table_Investimentos_Main[[#This Row],[Cotação Ativo]],Table_Investimentos_Main[[#This Row],[Quantidade]]) -> 198.9012
B40: 45292 | C40: Bitcoin | D40: BTC | E40: Binance | G40: 0.02 | H40: {=_xlfn.XLOOKUP(Table_Investimentos_Main[[#This Row],[Data]]&Table_Investimentos_Main[[#This Row],[Ticker]],Table_Cotacoes[Data]&Table_Cotacoes[Ticker],Table_Cotacoes[Valor],"")} -> 213280 | I40: =IF(Table_Investimentos_Main[[#This Row],[Ticker]]<>"",_xlfn.XLOOKUP(Table_Investimentos_Main[[#This Row],[Ticker]],Table_Cotacoes[Ticker],Table_Cotacoes[Moeda Base],""),"BRL") -> BTC | J40: {=_xlfn.SINGLE(_xlfn.XLOOKUP(Table_Investimentos_Main[[#This Row],[Data]]&"USD",Table_Cotacoes[Data]&Table_Cotacoes[Ticker],Table_Cotacoes[Valor],""))} -> 4.98 | K40: =IF(Table_Investimentos_Main[[#This Row],[Ticker]]<>"",Table_Investimentos_Main[[#This Row],[Quantidade]]*Table_Investimentos_Main[[#This Row],[Cotação Ativo]],Table_Investimentos_Main[[#This Row],[Quantidade]]) -> 4265.6
B41: 45292 | C41: Bitcoin | D41: BTC | E41: Carteira Cripto | G41: 0.18 | H41: {=_xlfn.XLOOKUP(Table_Investimentos_Main[[#This Row],[Data]]&Table_Investimentos_Main[[#This Row],[Ticker]],Table_Cotacoes[Data]&Table_Cotacoes[Ticker],Table_Cotacoes[Valor],"")} -> 213280 | I41: =IF(Table_Investimentos_Main[[#This Row],[Ticker]]<>"",_xlfn.XLOOKUP(Table_Investimentos_Main[[#This Row],[Ticker]],Table_Cotacoes[Ticker],Table_Cotacoes[Moeda Base],""),"BRL") -> BTC | J41: {=_xlfn.SINGLE(_xlfn.XLOOKUP(Table_Investimentos_Main[[#This Row],[Data]]&"USD",Table_Cotacoes[Data]&Table_Cotacoes[Ticker],Table_Cotacoes[Valor],""))} -> 4.98 | K41: =IF(Table_Investimentos_Main[[#This Row],[Ticker]]<>"",Table_Investimentos_Main[[#This Row],[Quantidade]]*Table_Investimentos_Main[[#This Row],[Cotação Ativo]],Table_Investimentos_Main[[#This Row],[Quantidade]]) -> 38390.4
B42: 45292 | C42: CDB Diario 105% | E42: C6 | G42: 29644.52 | H42: {=_xlfn.XLOOKUP(Table_Investimentos_Main[[#This Row],[Data]]&Table_Investimentos_Main[[#This Row],[Ticker]],Table_Cotacoes[Data]&Table_Cotacoes[Ticker],Table_Cotacoes[Valor],"")} | I42: =IF(Table_Investimentos_Main[[#This Row],[Ticker]]<>"",_xlfn.XLOOKUP(Table_Investimentos_Main[[#This Row],[Ticker]],Table_Cotacoes[Ticker],Table_Cotacoes[Moeda Base],""),"BRL") -> BRL | J42: {=_xlfn.SINGLE(_xlfn.XLOOKUP(Table_Investimentos_Main[[#This Row],[Data]]&"USD",Table_Cotacoes[Data]&Table_Cotacoes[Ticker],Table_Cotacoes[Valor],""))} -> 4.98 | K42: =IF(Table_Investimentos_Main[[#This Row],[Ticker]]<>"",Table_Investimentos_Main[[#This Row],[Quantidade]]*Table_Investimentos_Main[[#This Row],[Cotação Ativo]],Table_Investimentos_Main[[#This Row],[Quantidade]]) -> 29644.52
...

Sheet Investimentos_Porcent
B4: Data | C4: Nome | D4: Classe | E4: Subclasse | F4: Duração | G4: Estratégia | H4: Moeda Base | I4: Porcentagem | J4: Total (R$) | K4: Total ($)
B5: 46204 | C5: USDC | D5: Caixa | E5: Stablecoin | F5: D+0 | G5: {=_xlfn.XLOOKUP(Table_Investimentos_Porcent[[#This Row],[Data]]&Table_Investimentos_Porcent[[#This Row],[Nome]],Table_Investimentos_Main[Data]&Table_Investimentos_Main[Nome],Table_Investimentos_Main[Estratégia],"NOT FOUND")} -> Core | H5: {=_xlfn.XLOOKUP(Table_Investimentos_Porcent[[#This Row],[Data]]&Table_Investimentos_Porcent[[#This Row],[Nome]],Table_Investimentos_Main[Data]&Table_Investimentos_Main[Nome],Table_Investimentos_Main[Moeda Base],"NOT FOUND")} -> USD | I5: 1 | J5: {=Table_Investimentos_Porcent[[#This Row],[Porcentagem]]*_xlfn.XLOOKUP(Table_Investimentos_Porcent[[#This Row],[Data]]&Table_Investimentos_Porcent[[#This Row],[Nome]],Table_Investimentos_Main[Data]&Table_Investimentos_Main[Nome],Table_Investimentos_Main[Total (R$)],"NOT FOUND")} -> 8807.1311 | K5: {=Table_Investimentos_Porcent[[#This Row],[Total (R$)]]/_xlfn.XLOOKUP(Table_Investimentos_Porcent[[#This Row],[Data]]&Table_Investimentos_Porcent[[#This Row],[Nome]],Table_Investimentos_Main[Data]&Table_Investimentos_Main[Nome],Table_Investimentos_Main[Cotação Dolar],"NOT FOUND")} -> 1704.76
B6: 46204 | C6: Bitcoin 02 | D6: Cripto | E6: BTC | F6: - | G6: {=_xlfn.XLOOKUP(Table_Investimentos_Porcent[[#This Row],[Data]]&Table_Investimentos_Porcent[[#This Row],[Nome]],Table_Investimentos_Main[Data]&Table_Investimentos_Main[Nome],Table_Investimentos_Main[Estratégia],"NOT FOUND")} -> Core-Satellite | H6: {=_xlfn.XLOOKUP(Table_Investimentos_Porcent[[#This Row],[Data]]&Table_Investimentos_Porcent[[#This Row],[Nome]],Table_Investimentos_Main[Data]&Table_Investimentos_Main[Nome],Table_Investimentos_Main[Moeda Base],"NOT FOUND")} -> BTC | I6: 1 | J6: {=Table_Investimentos_Porcent[[#This Row],[Porcentagem]]*_xlfn.XLOOKUP(Table_Investimentos_Porcent[[#This Row],[Data]]&Table_Investimentos_Porcent[[#This Row],[Nome]],Table_Investimentos_Main[Data]&Table_Investimentos_Main[Nome],Table_Investimentos_Main[Total (R$)],"NOT FOUND")} -> 1957.8315 | K6: {=Table_Investimentos_Porcent[[#This Row],[Total (R$)]]/_xlfn.XLOOKUP(Table_Investimentos_Porcent[[#This Row],[Data]]&Table_Investimentos_Porcent[[#This Row],[Nome]],Table_Investimentos_Main[Data]&Table_Investimentos_Main[Nome],Table_Investimentos_Main[Cotação Dolar],"NOT FOUND")} -> 378.96936
B7: 46204 | C7: Solana | D7: Cripto | E7: Altcoin | F7: - | G7: {=_xlfn.XLOOKUP(Table_Investimentos_Porcent[[#This Row],[Data]]&Table_Investimentos_Porcent[[#This Row],[Nome]],Table_Investimentos_Main[Data]&Table_Investimentos_Main[Nome],Table_Investimentos_Main[Estratégia],"NOT FOUND")} -> Satellite | H7: {=_xlfn.XLOOKUP(Table_Investimentos_Porcent[[#This Row],[Data]]&Table_Investimentos_Porcent[[#This Row],[Nome]],Table_Investimentos_Main[Data]&Table_Investimentos_Main[Nome],Table_Investimentos_Main[Moeda Base],"NOT FOUND")} -> USD | I7: 1 | J7: {=Table_Investimentos_Porcent[[#This Row],[Porcentagem]]*_xlfn.XLOOKUP(Table_Investimentos_Porcent[[#This Row],[Data]]&Table_Investimentos_Porcent[[#This Row],[Nome]],Table_Investimentos_Main[Data]&Table_Investimentos_Main[Nome],Table_Investimentos_Main[Total (R$)],"NOT FOUND")} -> 2435.167 | K7: {=Table_Investimentos_Porcent[[#This Row],[Total (R$)]]/_xlfn.XLOOKUP(Table_Investimentos_Porcent[[#This Row],[Data]]&Table_Investimentos_Porcent[[#This Row],[Nome]],Table_Investimentos_Main[Data]&Table_Investimentos_Main[Nome],Table_Investimentos_Main[Cotação Dolar],"NOT FOUND")} -> 471.36522
B8: 46204 | C8: Time Deposit | D8: Caixa | E8: Pós-fixado | F8: Curto | G8: {=_xlfn.XLOOKUP(Table_Investimentos_Porcent[[#This Row],[Data]]&Table_Investimentos_Porcent[[#This Row],[Nome]],Table_Investimentos_Main[Data]&Table_Investimentos_Main[Nome],Table_Investimentos_Main[Estratégia],"NOT FOUND")} -> Core | H8: {=_xlfn.XLOOKUP(Table_Investimentos_Porcent[[#This Row],[Data]]&Table_Investimentos_Porcent[[#This Row],[Nome]],Table_Investimentos_Main[Data]&Table_Investimentos_Main[Nome],Table_Investimentos_Main[Moeda Base],"NOT FOUND")} -> USD | I8: 1 | J8: {=Table_Investimentos_Porcent[[#This Row],[Porcentagem]]*_xlfn.XLOOKUP(Table_Investimentos_Porcent[[#This Row],[Data]]&Table_Investimentos_Porcent[[#This Row],[Nome]],Table_Investimentos_Main[Data]&Table_Investimentos_Main[Nome],Table_Investimentos_Main[Total (R$)],"NOT FOUND")} -> 1331.1748 | K8: {=Table_Investimentos_Porcent[[#This Row],[Total (R$)]]/_xlfn.XLOOKUP(Table_Investimentos_Porcent[[#This Row],[Data]]&Table_Investimentos_Porcent[[#This Row],[Nome]],Table_Investimentos_Main[Data]&Table_Investimentos_Main[Nome],Table_Investimentos_Main[Cotação Dolar],"NOT FOUND")} -> 257.67
B9: 46204 | C9: Flexible Account | D9: Caixa | E9: Curto | F9: D+0 | G9: {=_xlfn.XLOOKUP(Table_Investimentos_Porcent[[#This Row],[Data]]&Table_Investimentos_Porcent[[#This Row],[Nome]],Table_Investimentos_Main[Data]&Table_Investimentos_Main[Nome],Table_Investimentos_Main[Estratégia],"NOT FOUND")} -> Core | H9: {=_xlfn.XLOOKUP(Table_Investimentos_Porcent[[#This Row],[Data]]&Table_Investimentos_Porcent[[#This Row],[Nome]],Table_Investimentos_Main[Data]&Table_Investimentos_Main[Nome],Table_Investimentos_Main[Moeda Base],"NOT FOUND")} -> USD | I9: 1 | J9: {=Table_Investimentos_Porcent[[#This Row],[Porcentagem]]*_xlfn.XLOOKUP(Table_Investimentos_Porcent[[#This Row],[Data]]&Table_Investimentos_Porcent[[#This Row],[Nome]],Table_Investimentos_Main[Data]&Table_Investimentos_Main[Nome],Table_Investimentos_Main[Total (R$)],"NOT FOUND")} -> 2991.2815 | K9: {=Table_Investimentos_Porcent[[#This Row],[Total (R$)]]/_xlfn.XLOOKUP(Table_Investimentos_Porcent[[#This Row],[Data]]&Table_Investimentos_Porcent[[#This Row],[Nome]],Table_Investimentos_Main[Data]&Table_Investimentos_Main[Nome],Table_Investimentos_Main[Cotação Dolar],"NOT FOUND")} -> 579.01
B10: 46204 | C10: ETF - GLDM | D10: Reserva | E10: Commoditie | F10: - | G10: {=_xlfn.XLOOKUP(Table_Investimentos_Porcent[[#This Row],[Data]]&Table_Investimentos_Porcent[[#This Row],[Nome]],Table_Investimentos_Main[Data]&Table_Investimentos_Main[Nome],Table_Investimentos_Main[Estratégia],"NOT FOUND")} -> Hedge | H10: {=_xlfn.XLOOKUP(Table_Investimentos_Porcent[[#This Row],[Data]]&Table_Investimentos_Porcent[[#This Row],[Nome]],Table_Investimentos_Main[Data]&Table_Investimentos_Main[Nome],Table_Investimentos_Main[Moeda Base],"NOT FOUND")} -> USD | I10: 1 | J10: {=Table_Investimentos_Porcent[[#This Row],[Porcentagem]]*_xlfn.XLOOKUP(Table_Investimentos_Porcent[[#This Row],[Data]]&Table_Investimentos_Porcent[[#This Row],[Nome]],Table_Investimentos_Main[Data]&Table_Investimentos_Main[Nome],Table_Investimentos_Main[Total (R$)],"NOT FOUND")} -> 5764.7618 | K10: {=Table_Investimentos_Porcent[[#This Row],[Total (R$)]]/_xlfn.XLOOKUP(Table_Investimentos_Porcent[[#This Row],[Data]]&Table_Investimentos_Porcent[[#This Row],[Nome]],Table_Investimentos_Main[Data]&Table_Investimentos_Main[Nome],Table_Investimentos_Main[Cotação Dolar],"NOT FOUND")} -> 1115.8611
B11: 46204 | C11: ETF - GPCA11 | D11: Renda Fixa | E11: IPCA | F11: Curto | G11: {=_xlfn.XLOOKUP(Table_Investimentos_Porcent[[#This Row],[Data]]&Table_Investimentos_Porcent[[#This Row],[Nome]],Table_Investimentos_Main[Data]&Table_Investimentos_Main[Nome],Table_Investimentos_Main[Estratégia],"NOT FOUND")} -> Core | H11: {=_xlfn.XLOOKUP(Table_Investimentos_Porcent[[#This Row],[Data]]&Table_Investimentos_Porcent[[#This Row],[Nome]],Table_Investimentos_Main[Data]&Table_Investimentos_Main[Nome],Table_Investimentos_Main[Moeda Base],"NOT FOUND")} -> BRL | I11: 0.6 | J11: {=Table_Investimentos_Porcent[[#This Row],[Porcentagem]]*_xlfn.XLOOKUP(Table_Investimentos_Porcent[[#This Row],[Data]]&Table_Investimentos_Porcent[[#This Row],[Nome]],Table_Investimentos_Main[Data]&Table_Investimentos_Main[Nome],Table_Investimentos_Main[Total (R$)],"NOT FOUND")} -> 3002.076 | K11: {=Table_Investimentos_Porcent[[#This Row],[Total (R$)]]/_xlfn.XLOOKUP(Table_Investimentos_Porcent[[#This Row],[Data]]&Table_Investimentos_Porcent[[#This Row],[Nome]],Table_Investimentos_Main[Data]&Table_Investimentos_Main[Nome],Table_Investimentos_Main[Cotação Dolar],"NOT FOUND")} -> 581.09945
B12: 46204 | C12: Tesouro IPCA+ 2032 | D12: Renda Fixa | E12: IPCA | F12: Médio | G12: {=_xlfn.XLOOKUP(Table_Investimentos_Porcent[[#This Row],[Data]]&Table_Investimentos_Porcent[[#This Row],[Nome]],Table_Investimentos_Main[Data]&Table_Investimentos_Main[Nome],Table_Investimentos_Main[Estratégia],"NOT FOUND")} -> Core | H12: {=_xlfn.XLOOKUP(Table_Investimentos_Porcent[[#This Row],[Data]]&Table_Investimentos_Porcent[[#This Row],[Nome]],Table_Investimentos_Main[Data]&Table_Investimentos_Main[Nome],Table_Investimentos_Main[Moeda Base],"NOT FOUND")} -> BRL | I12: 1 | J12: {=Table_Investimentos_Porcent[[#This Row],[Porcentagem]]*_xlfn.XLOOKUP(Table_Investimentos_Porcent[[#This Row],[Data]]&Table_Investimentos_Porcent[[#This Row],[Nome]],Table_Investimentos_Main[Data]&Table_Investimentos_Main[Nome],Table_Investimentos_Main[Total (R$)],"NOT FOUND")} -> 2986.86 | K12: {=Table_Investimentos_Porcent[[#This Row],[Total (R$)]]/_xlfn.XLOOKUP(Table_Investimentos_Porcent[[#This Row],[Data]]&Table_Investimentos_Porcent[[#This Row],[Nome]],Table_Investimentos_Main[Data]&Table_Investimentos_Main[Nome],Table_Investimentos_Main[Cotação Dolar],"NOT FOUND")} -> 578.15416
B13: 46204 | C13: ETF - GPCA11 | D13: Renda Fixa | E13: IPCA | F13: Médio | G13: {=_xlfn.XLOOKUP(Table_Investimentos_Porcent[[#This Row],[Data]]&Table_Investimentos_Porcent[[#This Row],[Nome]],Table_Investimentos_Main[Data]&Table_Investimentos_Main[Nome],Table_Investimentos_Main[Estratégia],"NOT FOUND")} -> Core | H13: {=_xlfn.XLOOKUP(Table_Investimentos_Porcent[[#This Row],[Data]]&Table_Investimentos_Porcent[[#This Row],[Nome]],Table_Investimentos_Main[Data]&Table_Investimentos_Main[Nome],Table_Investimentos_Main[Moeda Base],"NOT FOUND")} -> BRL | I13: 0.4 | J13: {=Table_Investimentos_Porcent[[#This Row],[Porcentagem]]*_xlfn.XLOOKUP(Table_Investimentos_Porcent[[#This Row],[Data]]&Table_Investimentos_Porcent[[#This Row],[Nome]],Table_Investimentos_Main[Data]&Table_Investimentos_Main[Nome],Table_Investimentos_Main[Total (R$)],"NOT FOUND")} -> 2001.384 | K13: {=Table_Investimentos_Porcent[[#This Row],[Total (R$)]]/_xlfn.XLOOKUP(Table_Investimentos_Porcent[[#This Row],[Data]]&Table_Investimentos_Porcent[[#This Row],[Nome]],Table_Investimentos_Main[Data]&Table_Investimentos_Main[Nome],Table_Investimentos_Main[Cotação Dolar],"NOT FOUND")} -> 387.39964
B14: 46204 | C14: ETF - IAUM | D14: Reserva | E14: Commoditie | F14: - | G14: {=_xlfn.XLOOKUP(Table_Investimentos_Porcent[[#This Row],[Data]]&Table_Investimentos_Porcent[[#This Row],[Nome]],Table_Investimentos_Main[Data]&Table_Investimentos_Main[Nome],Table_Investimentos_Main[Estratégia],"NOT FOUND")} -> Hedge | H14: {=_xlfn.XLOOKUP(Table_Investimentos_Porcent[[#This Row],[Data]]&Table_Investimentos_Porcent[[#This Row],[Nome]],Table_Investimentos_Main[Data]&Table_Investimentos_Main[Nome],Table_Investimentos_Main[Moeda Base],"NOT FOUND")} -> USD | I14: 1 | J14: {=Table_Investimentos_Porcent[[#This Row],[Porcentagem]]*_xlfn.XLOOKUP(Table_Investimentos_Porcent[[#This Row],[Data]]&Table_Investimentos_Porcent[[#This Row],[Nome]],Table_Investimentos_Main[Data]&Table_Investimentos_Main[Nome],Table_Investimentos_Main[Total (R$)],"NOT FOUND")} -> 4695.6773 | K14: {=Table_Investimentos_Porcent[[#This Row],[Total (R$)]]/_xlfn.XLOOKUP(Table_Investimentos_Porcent[[#This Row],[Data]]&Table_Investimentos_Porcent[[#This Row],[Nome]],Table_Investimentos_Main[Data]&Table_Investimentos_Main[Nome],Table_Investimentos_Main[Cotação Dolar],"NOT FOUND")} -> 908.92287
B15: 46204 | C15: ETF - SIVR | D15: Renda Variável | E15: Commoditie | F15: - | G15: {=_xlfn.XLOOKUP(Table_Investimentos_Porcent[[#This Row],[Data]]&Table_Investimentos_Porcent[[#This Row],[Nome]],Table_Investimentos_Main[Data]&Table_Investimentos_Main[Nome],Table_Investimentos_Main[Estratégia],"NOT FOUND")} -> Satellite | H15: {=_xlfn.XLOOKUP(Table_Investimentos_Porcent[[#This Row],[Data]]&Table_Investimentos_Porcent[[#This Row],[Nome]],Table_Investimentos_Main[Data]&Table_Investimentos_Main[Nome],Table_Investimentos_Main[Moeda Base],"NOT FOUND")} -> USD | I15: 1 | J15: {=Table_Investimentos_Porcent[[#This Row],[Porcentagem]]*_xlfn.XLOOKUP(Table_Investimentos_Porcent[[#This Row],[Data]]&Table_Investimentos_Porcent[[#This Row],[Nome]],Table_Investimentos_Main[Data]&Table_Investimentos_Main[Nome],Table_Investimentos_Main[Total (R$)],"NOT FOUND")} -> 908.10688 | K15: {=Table_Investimentos_Porcent[[#This Row],[Total (R$)]]/_xlfn.XLOOKUP(Table_Investimentos_Porcent[[#This Row],[Data]]&Table_Investimentos_Porcent[[#This Row],[Nome]],Table_Investimentos_Main[Data]&Table_Investimentos_Main[Nome],Table_Investimentos_Main[Cotação Dolar],"NOT FOUND")} -> 175.7785
B16: 46204 | C16: ETF - VOO | D16: Renda Variável | E16: Ações EUA | F16: - | G16: {=_xlfn.XLOOKUP(Table_Investimentos_Porcent[[#This Row],[Data]]&Table_Investimentos_Porcent[[#This Row],[Nome]],Table_Investimentos_Main[Data]&Table_Investimentos_Main[Nome],Table_Investimentos_Main[Estratégia],"NOT FOUND")} -> Core | H16: {=_xlfn.XLOOKUP(Table_Investimentos_Porcent[[#This Row],[Data]]&Table_Investimentos_Porcent[[#This Row],[Nome]],Table_Investimentos_Main[Data]&Table_Investimentos_Main[Nome],Table_Investimentos_Main[Moeda Base],"NOT FOUND")} -> USD | I16: 1 | J16: {=Table_Investimentos_Porcent[[#This Row],[Porcentagem]]*_xlfn.XLOOKUP(Table_Investimentos_Porcent[[#This Row],[Data]]&Table_Investimentos_Porcent[[#This Row],[Nome]],Table_Investimentos_Main[Data]&Table_Investimentos_Main[Nome],Table_Investimentos_Main[Total (R$)],"NOT FOUND")} -> 9918.2626 | K16: {=Table_Investimentos_Porcent[[#This Row],[Total (R$)]]/_xlfn.XLOOKUP(Table_Investimentos_Porcent[[#This Row],[Data]]&Table_Investimentos_Porcent[[#This Row],[Nome]],Table_Investimentos_Main[Data]&Table_Investimentos_Main[Nome],Table_Investimentos_Main[Cotação Dolar],"NOT FOUND")} -> 1919.8371
... B30: 46204 | C30: Tesouro IPCA Renda+ 2065 | D30: Renda Fixa | E30: IPCA | F30: Longo | G30: {=_xlfn.XLOOKUP(Table_Investimentos_Porcent[[#This Row],[Data]]&Table_Investimentos_Porcent[[#This Row],[Nome]],Table_Investimentos_Main[Data]&Table_Investimentos_Main[Nome],Table_Investimentos_Main[Estratégia],"NOT FOUND")} -> Core | H30: {=_xlfn.XLOOKUP(Table_Investimentos_Porcent[[#This Row],[Data]]&Table_Investimentos_Porcent[[#This Row],[Nome]],Table_Investimentos_Main[Data]&Table_Investimentos_Main[Nome],Table_Investimentos_Main[Moeda Base],"NOT FOUND")} -> BRL | I30: 1 | J30: {=Table_Investimentos_Porcent[[#This Row],[Porcentagem]]*_xlfn.XLOOKUP(Table_Investimentos_Porcent[[#This Row],[Data]]&Table_Investimentos_Porcent[[#This Row],[Nome]],Table_Investimentos_Main[Data]&Table_Investimentos_Main[Nome],Table_Investimentos_Main[Total (R$)],"NOT FOUND")} -> 11955.66 | K30: {=Table_Investimentos_Porcent[[#This Row],[Total (R$)]]/_xlfn.XLOOKUP(Table_Investimentos_Porcent[[#This Row],[Data]]&Table_Investimentos_Porcent[[#This Row],[Nome]],Table_Investimentos_Main[Data]&Table_Investimentos_Main[Nome],Table_Investimentos_Main[Cotação Dolar],"NOT FOUND")} -> 2314.2077
B31: 45078 | C31: Bitcoin | D31: Cripto | G31: {=_xlfn.XLOOKUP(Table_Investimentos_Porcent[[#This Row],[Data]]&Table_Investimentos_Porcent[[#This Row],[Nome]],Table_Investimentos_Main[Data]&Table_Investimentos_Main[Nome],Table_Investimentos_Main[Estratégia],"NOT FOUND")} -> 0 | H31: {=_xlfn.XLOOKUP(Table_Investimentos_Porcent[[#This Row],[Data]]&Table_Investimentos_Porcent[[#This Row],[Nome]],Table_Investimentos_Main[Data]&Table_Investimentos_Main[Nome],Table_Investimentos_Main[Moeda Base],"NOT FOUND")} -> BTC | I31: 1 | J31: {=Table_Investimentos_Porcent[[#This Row],[Porcentagem]]*_xlfn.XLOOKUP(Table_Investimentos_Porcent[[#This Row],[Data]]&Table_Investimentos_Porcent[[#This Row],[Nome]],Table_Investimentos_Main[Data]&Table_Investimentos_Main[Nome],Table_Investimentos_Main[Total (R$)],"NOT FOUND")} -> 24200.643 | K31: {=Table_Investimentos_Porcent[[#This Row],[Total (R$)]]/_xlfn.XLOOKUP(Table_Investimentos_Porcent[[#This Row],[Data]]&Table_Investimentos_Porcent[[#This Row],[Nome]],Table_Investimentos_Main[Data]&Table_Investimentos_Main[Nome],Table_Investimentos_Main[Cotação Dolar],"NOT FOUND")} -> 4833.3619
B32: 45078 | C32: Liquidez Diaria | D32: Caixa | G32: {=_xlfn.XLOOKUP(Table_Investimentos_Porcent[[#This Row],[Data]]&Table_Investimentos_Porcent[[#This Row],[Nome]],Table_Investimentos_Main[Data]&Table_Investimentos_Main[Nome],Table_Investimentos_Main[Estratégia],"NOT FOUND")} -> 0 | H32: {=_xlfn.XLOOKUP(Table_Investimentos_Porcent[[#This Row],[Data]]&Table_Investimentos_Porcent[[#This Row],[Nome]],Table_Investimentos_Main[Data]&Table_Investimentos_Main[Nome],Table_Investimentos_Main[Moeda Base],"NOT FOUND")} -> BRL | I32: 1 | J32: {=Table_Investimentos_Porcent[[#This Row],[Porcentagem]]*_xlfn.XLOOKUP(Table_Investimentos_Porcent[[#This Row],[Data]]&Table_Investimentos_Porcent[[#This Row],[Nome]],Table_Investimentos_Main[Data]&Table_Investimentos_Main[Nome],Table_Investimentos_Main[Total (R$)],"NOT FOUND")} -> 3698.14 | K32: {=Table_Investimentos_Porcent[[#This Row],[Total (R$)]]/_xlfn.XLOOKUP(Table_Investimentos_Porcent[[#This Row],[Data]]&Table_Investimentos_Porcent[[#This Row],[Nome]],Table_Investimentos_Main[Data]&Table_Investimentos_Main[Nome],Table_Investimentos_Main[Cotação Dolar],"NOT FOUND")} -> 738.59397
B33: 45078 | C33: CDB - 110% | D33: Renda Fixa | G33: {=_xlfn.XLOOKUP(Table_Investimentos_Porcent[[#This Row],[Data]]&Table_Investimentos_Porcent[[#This Row],[Nome]],Table_Investimentos_Main[Data]&Table_Investimentos_Main[Nome],Table_Investimentos_Main[Estratégia],"NOT FOUND")} -> 0 | H33: {=_xlfn.XLOOKUP(Table_Investimentos_Porcent[[#This Row],[Data]]&Table_Investimentos_Porcent[[#This Row],[Nome]],Table_Investimentos_Main[Data]&Table_Investimentos_Main[Nome],Table_Investimentos_Main[Moeda Base],"NOT FOUND")} -> BRL | I33: 1 | J33: {=Table_Investimentos_Porcent[[#This Row],[Porcentagem]]*_xlfn.XLOOKUP(Table_Investimentos_Porcent[[#This Row],[Data]]&Table_Investimentos_Porcent[[#This Row],[Nome]],Table_Investimentos_Main[Data]&Table_Investimentos_Main[Nome],Table_Investimentos_Main[Total (R$)],"NOT FOUND")} -> 20017.71 | K33: {=Table_Investimentos_Porcent[[#This Row],[Total (R$)]]/_xlfn.XLOOKUP(Table_Investimentos_Porcent[[#This Row],[Data]]&Table_Investimentos_Porcent[[#This Row],[Nome]],Table_Investimentos_Main[Data]&Table_Investimentos_Main[Nome],Table_Investimentos_Main[Cotação Dolar],"NOT FOUND")} -> 3997.9449
B34: 45078 | C34: USDT | D34: Reserva | G34: {=_xlfn.XLOOKUP(Table_Investimentos_Porcent[[#This Row],[Data]]&Table_Investimentos_Porcent[[#This Row],[Nome]],Table_Investimentos_Main[Data]&Table_Investimentos_Main[Nome],Table_Investimentos_Main[Estratégia],"NOT FOUND")} -> 0 | H34: {=_xlfn.XLOOKUP(Table_Investimentos_Porcent[[#This Row],[Data]]&Table_Investimentos_Porcent[[#This Row],[Nome]],Table_Investimentos_Main[Data]&Table_Investimentos_Main[Nome],Table_Investimentos_Main[Moeda Base],"NOT FOUND")} -> USD | I34: 1 | J34: {=Table_Investimentos_Porcent[[#This Row],[Porcentagem]]*_xlfn.XLOOKUP(Table_Investimentos_Porcent[[#This Row],[Data]]&Table_Investimentos_Porcent[[#This Row],[Nome]],Table_Investimentos_Main[Data]&Table_Investimentos_Main[Nome],Table_Investimentos_Main[Total (R$)],"NOT FOUND")} -> 5017.014 | K34: {=Table_Investimentos_Porcent[[#This Row],[Total (R$)]]/_xlfn.XLOOKUP(Table_Investimentos_Porcent[[#This Row],[Data]]&Table_Investimentos_Porcent[[#This Row],[Nome]],Table_Investimentos_Main[Data]&Table_Investimentos_Main[Nome],Table_Investimentos_Main[Cotação Dolar],"NOT FOUND")} -> 1002
B35: 45078 | C35: BUSD | D35: Reserva | G35: {=_xlfn.XLOOKUP(Table_Investimentos_Porcent[[#This Row],[Data]]&Table_Investimentos_Porcent[[#This Row],[Nome]],Table_Investimentos_Main[Data]&Table_Investimentos_Main[Nome],Table_Investimentos_Main[Estratégia],"NOT FOUND")} -> 0 | H35: {=_xlfn.XLOOKUP(Table_Investimentos_Porcent[[#This Row],[Data]]&Table_Investimentos_Porcent[[#This Row],[Nome]],Table_Investimentos_Main[Data]&Table_Investimentos_Main[Nome],Table_Investimentos_Main[Moeda Base],"NOT FOUND")} -> USD | I35: 1 | J35: {=Table_Investimentos_Porcent[[#This Row],[Porcentagem]]*_xlfn.XLOOKUP(Table_Investimentos_Porcent[[#This Row],[Data]]&Table_Investimentos_Porcent[[#This Row],[Nome]],Table_Investimentos_Main[Data]&Table_Investimentos_Main[Nome],Table_Investimentos_Main[Total (R$)],"NOT FOUND")} -> 12652.689 | K35: {=Table_Investimentos_Porcent[[#This Row],[Total (R$)]]/_xlfn.XLOOKUP(Table_Investimentos_Porcent[[#This Row],[Data]]&Table_Investimentos_Porcent[[#This Row],[Nome]],Table_Investimentos_Main[Data]&Table_Investimentos_Main[Nome],Table_Investimentos_Main[Cotação Dolar],"NOT FOUND")} -> 2527
B36: 45078 | C36: Dolar | D36: Reserva | G36: {=_xlfn.XLOOKUP(Table_Investimentos_Porcent[[#This Row],[Data]]&Table_Investimentos_Porcent[[#This Row],[Nome]],Table_Investimentos_Main[Data]&Table_Investimentos_Main[Nome],Table_Investimentos_Main[Estratégia],"NOT FOUND")} -> 0 | H36: {=_xlfn.XLOOKUP(Table_Investimentos_Porcent[[#This Row],[Data]]&Table_Investimentos_Porcent[[#This Row],[Nome]],Table_Investimentos_Main[Data]&Table_Investimentos_Main[Nome],Table_Investimentos_Main[Moeda Base],"NOT FOUND")} -> USD | I36: 1 | J36: {=Table_Investimentos_Porcent[[#This Row],[Porcentagem]]*_xlfn.XLOOKUP(Table_Investimentos_Porcent[[#This Row],[Data]]&Table_Investimentos_Porcent[[#This Row],[Nome]],Table_Investimentos_Main[Data]&Table_Investimentos_Main[Nome],Table_Investimentos_Main[Total (R$)],"NOT FOUND")} -> 499.64853 | K36: {=Table_Investimentos_Porcent[[#This Row],[Total (R$)]]/_xlfn.XLOOKUP(Table_Investimentos_Porcent[[#This Row],[Data]]&Table_Investimentos_Porcent[[#This Row],[Nome]],Table_Investimentos_Main[Data]&Table_Investimentos_Main[Nome],Table_Investimentos_Main[Cotação Dolar],"NOT FOUND")} -> 99.79
B37: 45108 | C37: Bitcoin | D37: Cripto | G37: {=_xlfn.XLOOKUP(Table_Investimentos_Porcent[[#This Row],[Data]]&Table_Investimentos_Porcent[[#This Row],[Nome]],Table_Investimentos_Main[Data]&Table_Investimentos_Main[Nome],Table_Investimentos_Main[Estratégia],"NOT FOUND")} -> 0 | H37: {=_xlfn.XLOOKUP(Table_Investimentos_Porcent[[#This Row],[Data]]&Table_Investimentos_Porcent[[#This Row],[Nome]],Table_Investimentos_Main[Data]&Table_Investimentos_Main[Nome],Table_Investimentos_Main[Moeda Base],"NOT FOUND")} -> BTC | I37: 1 | J37: {=Table_Investimentos_Porcent[[#This Row],[Porcentagem]]*_xlfn.XLOOKUP(Table_Investimentos_Porcent[[#This Row],[Data]]&Table_Investimentos_Porcent[[#This Row],[Nome]],Table_Investimentos_Main[Data]&Table_Investimentos_Main[Nome],Table_Investimentos_Main[Total (R$)],"NOT FOUND")} -> 27125.324 | K37: {=Table_Investimentos_Porcent[[#This Row],[Total (R$)]]/_xlfn.XLOOKUP(Table_Investimentos_Porcent[[#This Row],[Data]]&Table_Investimentos_Porcent[[#This Row],[Nome]],Table_Investimentos_Main[Data]&Table_Investimentos_Main[Nome],Table_Investimentos_Main[Cotação Dolar],"NOT FOUND")} -> 5547.1011
B38: 45108 | C38: Liquidez Diaria | D38: Caixa | G38: {=_xlfn.XLOOKUP(Table_Investimentos_Porcent[[#This Row],[Data]]&Table_Investimentos_Porcent[[#This Row],[Nome]],Table_Investimentos_Main[Data]&Table_Investimentos_Main[Nome],Table_Investimentos_Main[Estratégia],"NOT FOUND")} -> 0 | H38: {=_xlfn.XLOOKUP(Table_Investimentos_Porcent[[#This Row],[Data]]&Table_Investimentos_Porcent[[#This Row],[Nome]],Table_Investimentos_Main[Data]&Table_Investimentos_Main[Nome],Table_Investimentos_Main[Moeda Base],"NOT FOUND")} -> BRL | I38: 1 | J38: {=Table_Investimentos_Porcent[[#This Row],[Porcentagem]]*_xlfn.XLOOKUP(Table_Investimentos_Porcent[[#This Row],[Data]]&Table_Investimentos_Porcent[[#This Row],[Nome]],Table_Investimentos_Main[Data]&Table_Investimentos_Main[Nome],Table_Investimentos_Main[Total (R$)],"NOT FOUND")} -> 4238.83 | K38: {=Table_Investimentos_Porcent[[#This Row],[Total (R$)]]/_xlfn.XLOOKUP(Table_Investimentos_Porcent[[#This Row],[Data]]&Table_Investimentos_Porcent[[#This Row],[Nome]],Table_Investimentos_Main[Data]&Table_Investimentos_Main[Nome],Table_Investimentos_Main[Cotação Dolar],"NOT FOUND")} -> 866.8364
B39: 45108 | C39: CDB - 110% | D39: Renda Fixa | G39: {=_xlfn.XLOOKUP(Table_Investimentos_Porcent[[#This Row],[Data]]&Table_Investimentos_Porcent[[#This Row],[Nome]],Table_Investimentos_Main[Data]&Table_Investimentos_Main[Nome],Table_Investimentos_Main[Estratégia],"NOT FOUND")} -> 0 | H39: {=_xlfn.XLOOKUP(Table_Investimentos_Porcent[[#This Row],[Data]]&Table_Investimentos_Porcent[[#This Row],[Nome]],Table_Investimentos_Main[Data]&Table_Investimentos_Main[Nome],Table_Investimentos_Main[Moeda Base],"NOT FOUND")} -> BRL | I39: 1 | J39: {=Table_Investimentos_Porcent[[#This Row],[Porcentagem]]*_xlfn.XLOOKUP(Table_Investimentos_Porcent[[#This Row],[Data]]&Table_Investimentos_Porcent[[#This Row],[Nome]],Table_Investimentos_Main[Data]&Table_Investimentos_Main[Nome],Table_Investimentos_Main[Total (R$)],"NOT FOUND")} -> 20277.35 | K39: {=Table_Investimentos_Porcent[[#This Row],[Total (R$)]]/_xlfn.XLOOKUP(Table_Investimentos_Porcent[[#This Row],[Data]]&Table_Investimentos_Porcent[[#This Row],[Nome]],Table_Investimentos_Main[Data]&Table_Investimentos_Main[Nome],Table_Investimentos_Main[Cotação Dolar],"NOT FOUND")} -> 4146.6973
B40: 45108 | C40: USDT | D40: Caixa | G40: {=_xlfn.XLOOKUP(Table_Investimentos_Porcent[[#This Row],[Data]]&Table_Investimentos_Porcent[[#This Row],[Nome]],Table_Investimentos_Main[Data]&Table_Investimentos_Main[Nome],Table_Investimentos_Main[Estratégia],"NOT FOUND")} -> 0 | H40: {=_xlfn.XLOOKUP(Table_Investimentos_Porcent[[#This Row],[Data]]&Table_Investimentos_Porcent[[#This Row],[Nome]],Table_Investimentos_Main[Data]&Table_Investimentos_Main[Nome],Table_Investimentos_Main[Moeda Base],"NOT FOUND")} -> USD | I40: 1 | J40: {=Table_Investimentos_Porcent[[#This Row],[Porcentagem]]*_xlfn.XLOOKUP(Table_Investimentos_Porcent[[#This Row],[Data]]&Table_Investimentos_Porcent[[#This Row],[Nome]],Table_Investimentos_Main[Data]&Table_Investimentos_Main[Nome],Table_Investimentos_Main[Total (R$)],"NOT FOUND")} -> 4934.01 | K40: {=Table_Investimentos_Porcent[[#This Row],[Total (R$)]]/_xlfn.XLOOKUP(Table_Investimentos_Porcent[[#This Row],[Data]]&Table_Investimentos_Porcent[[#This Row],[Nome]],Table_Investimentos_Main[Data]&Table_Investimentos_Main[Nome],Table_Investimentos_Main[Cotação Dolar],"NOT FOUND")} -> 1009
